Workbook

Sheet Read Me
A1: Southern Water Corp. Economic Analysis
A11: In this unit, you've learned about the fundamentals of economics where you've covered supply, demand, and the principles of elasticity.
A12: In this case study, we'll seek to unpack these concepts, combining the economic analysis skills you've learned and have you apply this through your budding Excel capabilities!
A13: This case study will emphasize the use of AVERAGEIFS Formula and your charting capabilities, where you'll use these charts for a PowerPoint presentation you'll create at the end of this analysis!
A14: Good luck and let's get started!
A16: What do the tab colors in this workbook mean?
A17: Throughout the Case Study, we've split this into three sections. As you cover the relevant Economics concepts, you'll apply what you've learned in the exercise tabs. The order of completion is below: 1) Market Elasticity 2) Economic Cost Analysis 3) What-If Analysis
A18: Unpacking the Data Repository Table
A19: The data repository table might look scary at first, but all the data is logically grouped in a manner where the table can be read from left to right.
A20: Note that we've added in another table, the Water Trading Repository Table that shows the date and price at which either Soft or Hard water has been traded.
A32: Definitions
A33: We've included a high-level breakdown that explains the different columns you will deal with in the data repository and water trading repository table. Please read through this and familiarize yourself with what these columns mean.
A35: Account Type | B35: This column provides information on whether the dataset is referencing Financial Actuals (Money Spent) or Water Actuals (Volume of Water Produced).
A36: Value Drivers | B36: This is a pre-filled column mapping each Accounting Centre Code and Accounting Centre Code Element to either a Revenue Generating Activity (Revenues) or Cost Generating Activity (Expenses).
A37: Unit | B37: There are three desalination units or plants (facilities) owned by Southern Water Corp. These are the Kootha, Surjek and Jutik desalination units. The Unit column indicates, for that row of data, which Unit it applies towards.
A38: Month | B38: This represents the month that data was calculated for.
A39: Month (Number) | B39: This represents the month in numerical form.
A40: Accounting Code Centre | B40: Every row is mapped to an Accounting Code Centre. Based on the Accounting Code Centre (ACC) and the textual description, we know that all ACCs that mention Sales, are Profit Centres, and all ACCs that mention Costs, are Cost Centres. In Financial Accounting, Revenue-Generating Activities are mapped to Profit Centres (i.e. They generate profit), whilst Cost-Generating Activities are mapped to Cost Centres (i.e. They generate costs).
A41: Accounting Code Centre Element | B41: An Accounting Code Centre Element (ACCE) is made up of 'elements' which tie into the Accounting Code Centre.
A42: Unit of Measure | B42: Every Row of Data has a Unit of Measure (UoM) associated with this. E.g. Financial data is measured in dollars, whilst Water Production data is measure in Giga-Litres.
A43: Row Data | B43: This is the unique value that is stored for every row entry.
A44: Trading Interval | B44: The time-stamp where Water has been traded on the Open Water Market exchange database.
A45: Market Water Demand (Giga-Litres) | B45: The amount of water demanded by the Market for that respective time-stamp period.
A46: Water Balancing Price ($/ML) | B46: The Water Market Balancing Price that is settled by the Open Water Market exchange.
... A48: Water Type | B48: What type of Water Product is being traded (i.e. Hard Water or Soft Water)?
A51: Value Driver Trees
A52: Below we've included the Value Driver Trees for the Elasticity of Demand Coefficient; a critical calculation used to determine the elasticity (price sensitivity) of a product.

Sheet Data Repository Table
A1: Account Type | B1: Value Drivers | C1: Unit | D1: Month | E1: Month (Number) | F1: Centre Type | G1: Cost Centre / Profit Centre | H1: Cost Centre / Profit Centre Elements | I1: Unit of Measure | J1: Row Data
A2: Financial Actual | B2: Revenues | C2: Kootha | D2: 41456 | E2: =MONTH(D2) -> 7 | F2: Profit Centre | G2: 001 Private Water Hedge Sales | H2: W-Transact (0211) - Soft | I2: $ | J2: 1473589
A3: Financial Actual | B3: Revenues | C3: Kootha | D3: 41487 | E3: =MONTH(D3) -> 8 | F3: Profit Centre | G3: 001 Private Water Hedge Sales | H3: W-Transact (0211) - Soft | I3: $ | J3: 1419296.1
A4: Financial Actual | B4: Revenues | C4: Kootha | D4: 41518 | E4: =MONTH(D4) -> 9 | F4: Profit Centre | G4: 001 Private Water Hedge Sales | H4: W-Transact (0211) - Soft | I4: $ | J4: 1310673.2
A5: Financial Actual | B5: Revenues | C5: Kootha | D5: 41548 | E5: =MONTH(D5) -> 10 | F5: Profit Centre | G5: 001 Private Water Hedge Sales | H5: W-Transact (0211) - Soft | I5: $ | J5: 1301024.7
A6: Financial Actual | B6: Revenues | C6: Kootha | D6: 41579 | E6: =MONTH(D6) -> 11 | F6: Profit Centre | G6: 001 Private Water Hedge Sales | H6: W-Transact (0211) - Soft | I6: $ | J6: 1373822.9
A7: Financial Actual | B7: Revenues | C7: Kootha | D7: 41609 | E7: =MONTH(D7) -> 12 | F7: Profit Centre | G7: 001 Private Water Hedge Sales | H7: W-Transact (0211) - Soft | I7: $ | J7: 1340623
A8: Financial Actual | B8: Revenues | C8: Kootha | D8: 41640 | E8: =MONTH(D8) -> 1 | F8: Profit Centre | G8: 001 Private Water Hedge Sales | H8: W-Transact (0211) - Soft | I8: $ | J8: 1948962.6
A9: Financial Actual | B9: Revenues | C9: Kootha | D9: 41671 | E9: =MONTH(D9) -> 2 | F9: Profit Centre | G9: 001 Private Water Hedge Sales | H9: W-Transact (0211) - Soft | I9: $ | J9: 1725161.7
A10: Financial Actual | B10: Revenues | C10: Kootha | D10: 41699 | E10: =MONTH(D10) -> 3 | F10: Profit Centre | G10: 001 Private Water Hedge Sales | H10: W-Transact (0211) - Soft | I10: $ | J10: 1818208.6
A11: Financial Actual | B11: Revenues | C11: Kootha | D11: 41730 | E11: =MONTH(D11) -> 4 | F11: Profit Centre | G11: 001 Private Water Hedge Sales | H11: W-Transact (0211) - Soft | I11: $ | J11: 1328501.7
A12: Financial Actual | B12: Revenues | C12: Kootha | D12: 41760 | E12: =MONTH(D12) -> 5 | F12: Profit Centre | G12: 001 Private Water Hedge Sales | H12: W-Transact (0211) - Soft | I12: $ | J12: 1344117.3
A13: Financial Actual | B13: Revenues | C13: Kootha | D13: 41791 | E13: =MONTH(D13) -> 6 | F13: Profit Centre | G13: 001 Private Water Hedge Sales | H13: W-Transact (0211) - Soft | I13: $ | J13: 1291609.1
... A373: Financial Actual | B373: Expenses | C373: Surjek | D373: 41791 | E373: =MONTH(D373) -> 6 | F373: Cost Centre | G373: Labour Costs | H373: Labour-Costs (001) | I373: $ | J373: 1891504.3
A374: Financial Actual | B374: Expenses | C374: Jutik | D374: 41456 | E374: 7 | F374: Cost Centre | G374: Chemical Costs | H374: Chem-Exp (001) | I374: $ | J374: 1625596.3
A375: Financial Actual | B375: Expenses | C375: Jutik | D375: 41487 | E375: 8 | F375: Cost Centre | G375: Chemical Costs | H375: Chem-Exp (001) | I375: $ | J375: 1295067.8
A376: Financial Actual | B376: Expenses | C376: Jutik | D376: 41518 | E376: 9 | F376: Cost Centre | G376: Chemical Costs | H376: Chem-Exp (001) | I376: $ | J376: 1750624.9
A377: Financial Actual | B377: Expenses | C377: Jutik | D377: 41548 | E377: 10 | F377: Cost Centre | G377: Chemical Costs | H377: Chem-Exp (001) | I377: $ | J377: 1472529.4
A378: Financial Actual | B378: Expenses | C378: Jutik | D378: 41579 | E378: 11 | F378: Cost Centre | G378: Chemical Costs | H378: Chem-Exp (001) | I378: $ | J378: 1252200.5
A379: Financial Actual | B379: Expenses | C379: Jutik | D379: 41609 | E379: 12 | F379: Cost Centre | G379: Chemical Costs | H379: Chem-Exp (001) | I379: $ | J379: 1406782.7
A380: Financial Actual | B380: Expenses | C380: Jutik | D380: 41640 | E380: 1 | F380: Cost Centre | G380: Chemical Costs | H380: Chem-Exp (001) | I380: $ | J380: 1877449.5
A381: Financial Actual | B381: Expenses | C381: Jutik | D381: 41671 | E381: 2 | F381: Cost Centre | G381: Chemical Costs | H381: Chem-Exp (001) | I381: $ | J381: 1912219.2
A382: Financial Actual | B382: Expenses | C382: Jutik | D382: 41699 | E382: 3 | F382: Cost Centre | G382: Chemical Costs | H382: Chem-Exp (001) | I382: $ | J382: 2266625.2
A383: Financial Actual | B383: Expenses | C383: Jutik | D383: 41730 | E383: 4 | F383: Cost Centre | G383: Chemical Costs | H383: Chem-Exp (001) | I383: $ | J383: 2234200.6
A384: Financial Actual | B384: Expenses | C384: Jutik | D384: 41760 | E384: 5 | F384: Cost Centre | G384: Chemical Costs | H384: Chem-Exp (001) | I384: $ | J384: 2593715.6
A385: Financial Actual | B385: Expenses | C385: Jutik | D385: 41791 | E385: 6 | F385: Cost Centre | G385: Chemical Costs | H385: Chem-Exp (001) | I385: $ | J385: 2274807.8
... A505: Water Production Actuals | B505: None | C505: Jutik | D505: 41791 | E505: 6 | F505: None | G505: None | H505: None | I505: Giga-Litre | J505: 220.38033

Sheet Water Trading Repository Table
A1: Trading Interval | B1: Market Water Demand (Giga-Litres) | C1: Water Balancing Price ($/ML) | D1: Month | E1: Water Type
A2: 41640 | B2: 2674.4305 | C2: 89.33425 | D2: =MONTH(A2) -> 1 | E2: Soft
A3: 41640.5 | B3: 2576.1278 | C3: 61.946 | D3: =MONTH(A3) -> 1 | E3: Soft
A4: 41641 | B4: 2131.982 | C4: 45.90175 | D4: =MONTH(A4) -> 1 | E4: Soft
A5: 41641.5 | B5: 2772.056 | C5: 80.85825 | D5: =MONTH(A5) -> 1 | E5: Soft
A6: 41642 | B6: 2143.4866 | C6: 55.961833 | D6: =MONTH(A6) -> 1 | E6: Soft
A7: 41642.5 | B7: 2682.0311 | C7: 101.09483 | D7: =MONTH(A7) -> 1 | E7: Soft
A8: 41643 | B8: 1788.0747 | C8: 26.665 | D8: =MONTH(A8) -> 1 | E8: Soft
A9: 41643.5 | B9: 2082.8451 | C9: 38.894545 | D9: =MONTH(A9) -> 1 | E9: Soft
A10: 41644 | B10: 1815.8505 | C10: 46.715 | D10: =MONTH(A10) -> 1 | E10: Soft
A11: 41644.5 | B11: 2219.2754 | C11: 46.208636 | D11: =MONTH(A11) -> 1 | E11: Soft
A12: 41645 | B12: 2142.3453 | C12: 41.856 | D12: =MONTH(A12) -> 1 | E12: Soft
A13: 41645.5 | B13: 2169.7437 | C13: 46.01375 | D13: =MONTH(A13) -> 1 | E13: Soft
... A731: 42004.5 | B731: 2134.082 | C731: 42.499583 | D731: =MONTH(A731) -> 12 | E731: Soft
A732: 41640 | B732: 2814.7106 | C732: 108.1875 | D732: 1 | E732: Hard
A733: 41640.5 | B733: 2820.1593 | C733: 111.245 | D733: 1 | E733: Hard
A734: 41641 | B734: 2147.3532 | C734: 110.51333 | D734: 1 | E734: Hard
A735: 41641.5 | B735: 2545.3108 | C735: 109.415 | D735: 1 | E735: Hard
A736: 41642 | B736: 2222.4136 | C736: 109.89833 | D736: 1 | E736: Hard
A737: 41642.5 | B737: 2257.3158 | C737: 111.87083 | D737: 1 | E737: Hard
A738: 41643 | B738: 2032.1983 | C738: 108.641 | D738: 1 | E738: Hard
A739: 41643.5 | B739: 2117.8163 | C739: 112.475 | D739: 1 | E739: Hard
A740: 41644 | B740: 1881.95 | C740: 111.09333 | D740: 1 | E740: Hard
A741: 41644.5 | B741: 2576.3439 | C741: 111.43364 | D741: 1 | E741: Hard
A742: 41645 | B742: 2044.6648 | C742: 110.707 | D742: 1 | E742: Hard
A743: 41645.5 | B743: 2868.9563 | C743: 108.41083 | D743: 1 | E743: Hard
... A1461: 42004.5 | B1461: 2379.9689 | C1461: 96.1525 | D1461: 12 | E1461: Hard

Sheet Economic Market Analysis
A1: Economic Analysis - Part I
A2: In this economics unit we've introduced you to the concept of Elasticity and Inelasticity and the relation this has to pricing patterns for products.
A3: While you might not immediately understand the relationship between elasticity and pricing, it's important we take a moment to understand how this is linked.
A4: Say for example, if we suddenly had our Netflix account fees raise to $100 per month - a number of us might reconsider whether we still want this subscription. The insight here is that the product is elastic (i.e. If we increase the price too sharply, people will leave and go to other streaming platforms.)
A5: This is tied to the concept of Elasticity (i.e. When the price is low enough, demand is high. Inversely, when the price is high - demand reduces).
A6: Now, there are situations that even IF the price rises, we will still purchase the same quantity of goods.
A7: Take for example, a particular drug for a pre-existing medical condition. If the price were to rise from its current amount to 10% higher than usual - the amount demanded wouldn't decrease as the product is still required.
A8: When this occurs, the product is known as an INELASTIC PRODUCT. (i.e. Regardless of whether the demand increases or decreases, the price will not change in any substantial manner).
A9: With what you've learned, let's take a look at Southern Water Corps Economic Data and see what trends we can identify from an Elasticity and Inelasticity Perspective. Let's be objective and ask ourselves - what does the data tell us?
A10: Let's get started!
A11: Q1. Please calculate the Average Water Balancing Market Price (WBMP) and Average Quantities of Water Demanded for 1) Hard and Soft Water Combined, 2) Hard Water Only and 3) Soft Water Only across the Jan-14 to Dec-14 Period.
A12: Do you notice any trends when comparing the Price and Quantity Per Product? (Pay particular attention to the Pricing and the Quantities and put this in the yellow box we've highlighted below)
A13: Hard + Soft Water Table | C13: 41640 | D13: 41671 | E13: 41699 | F13: 41730 | G13: 41760 | H13: 41791 | I13: 41821 | J13: 41852 | K13: 41883 | L13: 41913 | M13: 41944 | N13: 41974
B14: Month # | C14: 1 | D14: 2 | E14: 3 | F14: 4 | G14: 5 | H14: 6 | I14: 7 | J14: 8 | K14: 9 | L14: 10 | M14: 11 | N14: 12
B15: Avg. Quantity of Soft + Hard Water | C15: =AVERAGEIFS('Water Trading Repository Table'!$B:$B,'Water Trading Repository Table'!$E:$E,"Soft",'Water Trading Repository Table'!$D:$D,C$14)+ AVERAGEIFS('Water Trading Repository Table'!$B:$B,'Water Trading Repository Table'!$E:$E,"Hard",'Water Trading Repository Table'!$D:$D,C$14) -> 4596.3803 | D15: =AVERAGEIFS('Water Trading Repository Table'!$B:$B,'Water Trading Repository Table'!$E:$E,"Soft",'Water Trading Repository Table'!$D:$D,D$14)+ AVERAGEIFS('Water Trading Repository Table'!$B:$B,'Water Trading Repository Table'!$E:$E,"Hard",'Water Trading Repository Table'!$D:$D,D$14) -> 4812.1838 | E15: =AVERAGEIFS('Water Trading Repository Table'!$B:$B,'Water Trading Repository Table'!$E:$E,"Soft",'Water Trading Repository Table'!$D:$D,E$14)+ AVERAGEIFS('Water Trading Repository Table'!$B:$B,'Water Trading Repository Table'!$E:$E,"Hard",'Water Trading Repository Table'!$D:$D,E$14) -> 4255.6291 | F15: =AVERAGEIFS('Water Trading Repository Table'!$B:$B,'Water Trading Repository Table'!$E:$E,"Soft",'Water Trading Repository Table'!$D:$D,F$14)+ AVERAGEIFS('Water Trading Repository Table'!$B:$B,'Water Trading Repository Table'!$E:$E,"Hard",'Water Trading Repository Table'!$D:$D,F$14) -> 4371.5995 | G15: =AVERAGEIFS('Water Trading Repository Table'!$B:$B,'Water Trading Repository Table'!$E:$E,"Soft",'Water Trading Repository Table'!$D:$D,G$14)+ AVERAGEIFS('Water Trading Repository Table'!$B:$B,'Water Trading Repository Table'!$E:$E,"Hard",'Water Trading Repository Table'!$D:$D,G$14) -> 4291.5674 | H15: =AVERAGEIFS('Water Trading Repository Table'!$B:$B,'Water Trading Repository Table'!$E:$E,"Soft",'Water Trading Repository Table'!$D:$D,H$14)+ AVERAGEIFS('Water Trading Repository Table'!$B:$B,'Water Trading Repository Table'!$E:$E,"Hard",'Water Trading Repository Table'!$D:$D,H$14) -> 4459.4993 | I15: =AVERAGEIFS('Water Trading Repository Table'!$B:$B,'Water Trading Repository Table'!$E:$E,"Soft",'Water Trading Repository Table'!$D:$D,I$14)+ AVERAGEIFS('Water Trading Repository Table'!$B:$B,'Water Trading Repository Table'!$E:$E,"Hard",'Water Trading Repository Table'!$D:$D,I$14) -> 4566.1005 | J15: =AVERAGEIFS('Water Trading Repository Table'!$B:$B,'Water Trading Repository Table'!$E:$E,"Soft",'Water Trading Repository Table'!$D:$D,J$14)+ AVERAGEIFS('Water Trading Repository Table'!$B:$B,'Water Trading Repository Table'!$E:$E,"Hard",'Water Trading Repository Table'!$D:$D,J$14) -> 4402.1185 | ... N15: =AVERAGEIFS('Water Trading Repository Table'!$B:$B,'Water Trading Repository Table'!$E:$E,"Soft",'Water Trading Repository Table'!$D:$D,N$14)+ AVERAGEIFS('Water Trading Repository Table'!$B:$B,'Water Trading Repository Table'!$E:$E,"Hard",'Water Trading Repository Table'!$D:$D,N$14) -> 4624.3991
B16: Avg. Water Market Balancing Price (WMBP) | C16: =AVERAGEIFS('Water Trading Repository Table'!$C:$C, 'Water Trading Repository Table'!$E:$E, "Soft", 'Water Trading Repository Table'!$D:$D, C$14) + AVERAGEIFS('Water Trading Repository Table'!$C:$C, 'Water Trading Repository Table'!$E:$E, "Hard", 'Water Trading Repository Table'!$D:$D, C$14) -> 172.78351 | D16: =AVERAGEIFS('Water Trading Repository Table'!$C:$C, 'Water Trading Repository Table'!$E:$E, "Soft", 'Water Trading Repository Table'!$D:$D, D$14) + AVERAGEIFS('Water Trading Repository Table'!$C:$C, 'Water Trading Repository Table'!$E:$E, "Hard", 'Water Trading Repository Table'!$D:$D, D$14) -> 173.65898 | E16: =AVERAGEIFS('Water Trading Repository Table'!$C:$C, 'Water Trading Repository Table'!$E:$E, "Soft", 'Water Trading Repository Table'!$D:$D, E$14) + AVERAGEIFS('Water Trading Repository Table'!$C:$C, 'Water Trading Repository Table'!$E:$E, "Hard", 'Water Trading Repository Table'!$D:$D, E$14) -> 162.99978 | F16: =AVERAGEIFS('Water Trading Repository Table'!$C:$C, 'Water Trading Repository Table'!$E:$E, "Soft", 'Water Trading Repository Table'!$D:$D, F$14) + AVERAGEIFS('Water Trading Repository Table'!$C:$C, 'Water Trading Repository Table'!$E:$E, "Hard", 'Water Trading Repository Table'!$D:$D, F$14) -> 145.13846 | G16: =AVERAGEIFS('Water Trading Repository Table'!$C:$C, 'Water Trading Repository Table'!$E:$E, "Soft", 'Water Trading Repository Table'!$D:$D, G$14) + AVERAGEIFS('Water Trading Repository Table'!$C:$C, 'Water Trading Repository Table'!$E:$E, "Hard", 'Water Trading Repository Table'!$D:$D, G$14) -> 142.51871 | H16: =AVERAGEIFS('Water Trading Repository Table'!$C:$C, 'Water Trading Repository Table'!$E:$E, "Soft", 'Water Trading Repository Table'!$D:$D, H$14) + AVERAGEIFS('Water Trading Repository Table'!$C:$C, 'Water Trading Repository Table'!$E:$E, "Hard", 'Water Trading Repository Table'!$D:$D, H$14) -> 144.31302 | I16: =AVERAGEIFS('Water Trading Repository Table'!$C:$C, 'Water Trading Repository Table'!$E:$E, "Soft", 'Water Trading Repository Table'!$D:$D, I$14) + AVERAGEIFS('Water Trading Repository Table'!$C:$C, 'Water Trading Repository Table'!$E:$E, "Hard", 'Water Trading Repository Table'!$D:$D, I$14) -> 153.20544 | J16: =AVERAGEIFS('Water Trading Repository Table'!$C:$C, 'Water Trading Repository Table'!$E:$E, "Soft", 'Water Trading Repository Table'!$D:$D, J$14) + AVERAGEIFS('Water Trading Repository Table'!$C:$C, 'Water Trading Repository Table'!$E:$E, "Hard", 'Water Trading Repository Table'!$D:$D, J$14) -> 149.86508 | ... N16: =AVERAGEIFS('Water Trading Repository Table'!$C:$C, 'Water Trading Repository Table'!$E:$E, "Soft", 'Water Trading Repository Table'!$D:$D, N$14) + AVERAGEIFS('Water Trading Repository Table'!$C:$C, 'Water Trading Repository Table'!$E:$E, "Hard", 'Water Trading Repository Table'!$D:$D, N$14) -> 148.75331
A17: Hard Water Table
A18: Hard | B18: Avg. Quantity of Hard Water | C18: =AVERAGEIFS('Water Trading Repository Table'!$B:$B,'Water Trading Repository Table'!$E:$E,"Hard",'Water Trading Repository Table'!$D:$D,C$14) -> 2391.3759 | D18: =AVERAGEIFS('Water Trading Repository Table'!$B:$B,'Water Trading Repository Table'!$E:$E,"Hard",'Water Trading Repository Table'!$D:$D,D$14) -> 2533.2689 | E18: =AVERAGEIFS('Water Trading Repository Table'!$B:$B,'Water Trading Repository Table'!$E:$E,"Hard",'Water Trading Repository Table'!$D:$D,E$14) -> 2203.7443 | F18: =AVERAGEIFS('Water Trading Repository Table'!$B:$B,'Water Trading Repository Table'!$E:$E,"Hard",'Water Trading Repository Table'!$D:$D,F$14) -> 2349.5141 | G18: =AVERAGEIFS('Water Trading Repository Table'!$B:$B,'Water Trading Repository Table'!$E:$E,"Hard",'Water Trading Repository Table'!$D:$D,G$14) -> 2243.5845 | H18: =AVERAGEIFS('Water Trading Repository Table'!$B:$B,'Water Trading Repository Table'!$E:$E,"Hard",'Water Trading Repository Table'!$D:$D,H$14) -> 2359.315 | I18: =AVERAGEIFS('Water Trading Repository Table'!$B:$B,'Water Trading Repository Table'!$E:$E,"Hard",'Water Trading Repository Table'!$D:$D,I$14) -> 2443.2652 | J18: =AVERAGEIFS('Water Trading Repository Table'!$B:$B,'Water Trading Repository Table'!$E:$E,"Hard",'Water Trading Repository Table'!$D:$D,J$14) -> 2300.8486 | ... N18: =AVERAGEIFS('Water Trading Repository Table'!$B:$B,'Water Trading Repository Table'!$E:$E,"Hard",'Water Trading Repository Table'!$D:$D,N$14) -> 2443.6005
B19: Avg. Water Market Balancing Price (WMBP) | C19: =AVERAGEIFS('Water Trading Repository Table'!$C:$C, 'Water Trading Repository Table'!$E:$E, "Hard", 'Water Trading Repository Table'!$D:$D, C$14) -> 110.48382 | D19: =AVERAGEIFS('Water Trading Repository Table'!$C:$C, 'Water Trading Repository Table'!$E:$E, "Hard", 'Water Trading Repository Table'!$D:$D, D$14) -> 110.6272 | E19: =AVERAGEIFS('Water Trading Repository Table'!$C:$C, 'Water Trading Repository Table'!$E:$E, "Hard", 'Water Trading Repository Table'!$D:$D, E$14) -> 110.55819 | F19: =AVERAGEIFS('Water Trading Repository Table'!$C:$C, 'Water Trading Repository Table'!$E:$E, "Hard", 'Water Trading Repository Table'!$D:$D, F$14) -> 93.175186 | G19: =AVERAGEIFS('Water Trading Repository Table'!$C:$C, 'Water Trading Repository Table'!$E:$E, "Hard", 'Water Trading Repository Table'!$D:$D, G$14) -> 93.40891 | H19: =AVERAGEIFS('Water Trading Repository Table'!$C:$C, 'Water Trading Repository Table'!$E:$E, "Hard", 'Water Trading Repository Table'!$D:$D, H$14) -> 92.851211 | I19: =AVERAGEIFS('Water Trading Repository Table'!$C:$C, 'Water Trading Repository Table'!$E:$E, "Hard", 'Water Trading Repository Table'!$D:$D, I$14) -> 92.809568 | J19: =AVERAGEIFS('Water Trading Repository Table'!$C:$C, 'Water Trading Repository Table'!$E:$E, "Hard", 'Water Trading Repository Table'!$D:$D, J$14) -> 93.14548 | ... N19: =AVERAGEIFS('Water Trading Repository Table'!$C:$C, 'Water Trading Repository Table'!$E:$E, "Hard", 'Water Trading Repository Table'!$D:$D, N$14) -> 93.232935
A20: Soft Water Table
A21: Soft | B21: Avg. Quantity of Soft Water | C21: =AVERAGEIFS('Water Trading Repository Table'!$B:$B,'Water Trading Repository Table'!$E:$E,"Soft",'Water Trading Repository Table'!$D:$D,C$14) -> 2205.0044 | D21: =AVERAGEIFS('Water Trading Repository Table'!$B:$B,'Water Trading Repository Table'!$E:$E,"Soft",'Water Trading Repository Table'!$D:$D,D$14) -> 2278.9149 | E21: =AVERAGEIFS('Water Trading Repository Table'!$B:$B,'Water Trading Repository Table'!$E:$E,"Soft",'Water Trading Repository Table'!$D:$D,E$14) -> 2051.8848 | F21: =AVERAGEIFS('Water Trading Repository Table'!$B:$B,'Water Trading Repository Table'!$E:$E,"Soft",'Water Trading Repository Table'!$D:$D,F$14) -> 2022.0854 | G21: =AVERAGEIFS('Water Trading Repository Table'!$B:$B,'Water Trading Repository Table'!$E:$E,"Soft",'Water Trading Repository Table'!$D:$D,G$14) -> 2047.9829 | H21: =AVERAGEIFS('Water Trading Repository Table'!$B:$B,'Water Trading Repository Table'!$E:$E,"Soft",'Water Trading Repository Table'!$D:$D,H$14) -> 2100.1844 | I21: =AVERAGEIFS('Water Trading Repository Table'!$B:$B,'Water Trading Repository Table'!$E:$E,"Soft",'Water Trading Repository Table'!$D:$D,I$14) -> 2122.8353 | J21: =AVERAGEIFS('Water Trading Repository Table'!$B:$B,'Water Trading Repository Table'!$E:$E,"Soft",'Water Trading Repository Table'!$D:$D,J$14) -> 2101.2699 | ... N21: =AVERAGEIFS('Water Trading Repository Table'!$B:$B,'Water Trading Repository Table'!$E:$E,"Soft",'Water Trading Repository Table'!$D:$D,N$14) -> 2180.7986
B22: Avg. Water Market Balancing Price (WMBP) | C22: =AVERAGEIFS('Water Trading Repository Table'!$C:$C, 'Water Trading Repository Table'!$E:$E, "Soft", 'Water Trading Repository Table'!$D:$D, C$14) -> 62.299699 | D22: =AVERAGEIFS('Water Trading Repository Table'!$C:$C, 'Water Trading Repository Table'!$E:$E, "Soft", 'Water Trading Repository Table'!$D:$D, D$14) -> 63.031777 | E22: =AVERAGEIFS('Water Trading Repository Table'!$C:$C, 'Water Trading Repository Table'!$E:$E, "Soft", 'Water Trading Repository Table'!$D:$D, E$14) -> 52.441594 | F22: =AVERAGEIFS('Water Trading Repository Table'!$C:$C, 'Water Trading Repository Table'!$E:$E, "Soft", 'Water Trading Repository Table'!$D:$D, F$14) -> 51.963278 | G22: =AVERAGEIFS('Water Trading Repository Table'!$C:$C, 'Water Trading Repository Table'!$E:$E, "Soft", 'Water Trading Repository Table'!$D:$D, G$14) -> 49.109798 | H22: =AVERAGEIFS('Water Trading Repository Table'!$C:$C, 'Water Trading Repository Table'!$E:$E, "Soft", 'Water Trading Repository Table'!$D:$D, H$14) -> 51.46181 | I22: =AVERAGEIFS('Water Trading Repository Table'!$C:$C, 'Water Trading Repository Table'!$E:$E, "Soft", 'Water Trading Repository Table'!$D:$D, I$14) -> 60.395873 | J22: =AVERAGEIFS('Water Trading Repository Table'!$C:$C, 'Water Trading Repository Table'!$E:$E, "Soft", 'Water Trading Repository Table'!$D:$D, J$14) -> 56.7196 | ... N22: =AVERAGEIFS('Water Trading Repository Table'!$C:$C, 'Water Trading Repository Table'!$E:$E, "Soft", 'Water Trading Repository Table'!$D:$D, N$14) -> 55.520378
A24: Place your answer here | B24: 🧩 1. Hard + Soft Water Combined Higher quantity months (e.g., Jan: 4596.38) tend to have higher prices (Jan: $172.78). As quantity decreases (Mar: 4255.63), prices also drop (Mar: $163.00). Suggests a positive relationship: when demand is high, price is high. 💧 2. Hard Water Quantity remains relatively stable (range: ~2200–2500), but price decreases steadily: Jan: $110.48 → Jul: $92.81 Even when quantity slightly increases (e.g., Jul), price does not increase. Implies a weak or no clear link between hard water quantity and price — price seems to be trending downward regardless. 💦 3. Soft Water Quantity increases from Mar (2051.88) to Jul (2122.84). Prices remain very low and relatively flat: ~$49–63 range. The price drop in Mar ($52.44) and May ($49.11) appears even when quantity is low, suggesting price is not tightly correlated with quantity for soft water. 🔍 Key Observations: | C24: 🧩 1. Hard + Soft Water Combined Higher quantity months (e.g., Jan: 4596.38) tend to have higher prices (Jan: $172.78). As quantity decreases (Mar: 4255.63), prices also drop (Mar: $163.00). Suggests a positive relationship: when demand is high, price is high. 💧 2. Hard Water Quantity remains relatively stable (range: ~2200–2500), but price decreases steadily: Jan: $110.48 → Jul: $92.81 Even when quantity slightly increases (e.g., Jul), price does not increase. Implies a weak or no clear link between hard water quantity and price — price seems to be trending downward regardless. 💦 3. Soft Water Quantity increases from Mar (2051.88) to Jul (2122.84). Prices remain very low and relatively flat: ~$49–63 range. The price drop in Mar ($52.44) and May ($49.11) appears even when quantity is low, suggesting price is not tightly correlated with quantity for soft water. 🔍 Key Observations: | D24: 🧩 1. Hard + Soft Water Combined Higher quantity months (e.g., Jan: 4596.38) tend to have higher prices (Jan: $172.78). As quantity decreases (Mar: 4255.63), prices also drop (Mar: $163.00). Suggests a positive relationship: when demand is high, price is high. 💧 2. Hard Water Quantity remains relatively stable (range: ~2200–2500), but price decreases steadily: Jan: $110.48 → Jul: $92.81 Even when quantity slightly increases (e.g., Jul), price does not increase. Implies a weak or no clear link between hard water quantity and price — price seems to be trending downward regardless. 💦 3. Soft Water Quantity increases from Mar (2051.88) to Jul (2122.84). Prices remain very low and relatively flat: ~$49–63 range. The price drop in Mar ($52.44) and May ($49.11) appears even when quantity is low, suggesting price is not tightly correlated with quantity for soft water. 🔍 Key Observations: | E24: 🧩 1. Hard + Soft Water Combined Higher quantity months (e.g., Jan: 4596.38) tend to have higher prices (Jan: $172.78). As quantity decreases (Mar: 4255.63), prices also drop (Mar: $163.00). Suggests a positive relationship: when demand is high, price is high. 💧 2. Hard Water Quantity remains relatively stable (range: ~2200–2500), but price decreases steadily: Jan: $110.48 → Jul: $92.81 Even when quantity slightly increases (e.g., Jul), price does not increase. Implies a weak or no clear link between hard water quantity and price — price seems to be trending downward regardless. 💦 3. Soft Water Quantity increases from Mar (2051.88) to Jul (2122.84). Prices remain very low and relatively flat: ~$49–63 range. The price drop in Mar ($52.44) and May ($49.11) appears even when quantity is low, suggesting price is not tightly correlated with quantity for soft water. 🔍 Key Observations: | F24: 🧩 1. Hard + Soft Water Combined Higher quantity months (e.g., Jan: 4596.38) tend to have higher prices (Jan: $172.78). As quantity decreases (Mar: 4255.63), prices also drop (Mar: $163.00). Suggests a positive relationship: when demand is high, price is high. 💧 2. Hard Water Quantity remains relatively stable (range: ~2200–2500), but price decreases steadily: Jan: $110.48 → Jul: $92.81 Even when quantity slightly increases (e.g., Jul), price does not increase. Implies a weak or no clear link between hard water quantity and price — price seems to be trending downward regardless. 💦 3. Soft Water Quantity increases from Mar (2051.88) to Jul (2122.84). Prices remain very low and relatively flat: ~$49–63 range. The price drop in Mar ($52.44) and May ($49.11) appears even when quantity is low, suggesting price is not tightly correlated with quantity for soft water. 🔍 Key Observations:
B25: 🧩 1. Hard + Soft Water Combined Higher quantity months (e.g., Jan: 4596.38) tend to have higher prices (Jan: $172.78). As quantity decreases (Mar: 4255.63), prices also drop (Mar: $163.00). Suggests a positive relationship: when demand is high, price is high. 💧 2. Hard Water Quantity remains relatively stable (range: ~2200–2500), but price decreases steadily: Jan: $110.48 → Jul: $92.81 Even when quantity slightly increases (e.g., Jul), price does not increase. Implies a weak or no clear link between hard water quantity and price — price seems to be trending downward regardless. 💦 3. Soft Water Quantity increases from Mar (2051.88) to Jul (2122.84). Prices remain very low and relatively flat: ~$49–63 range. The price drop in Mar ($52.44) and May ($49.11) appears even when quantity is low, suggesting price is not tightly correlated with quantity for soft water. 🔍 Key Observations: | C25: 🧩 1. Hard + Soft Water Combined Higher quantity months (e.g., Jan: 4596.38) tend to have higher prices (Jan: $172.78). As quantity decreases (Mar: 4255.63), prices also drop (Mar: $163.00). Suggests a positive relationship: when demand is high, price is high. 💧 2. Hard Water Quantity remains relatively stable (range: ~2200–2500), but price decreases steadily: Jan: $110.48 → Jul: $92.81 Even when quantity slightly increases (e.g., Jul), price does not increase. Implies a weak or no clear link between hard water quantity and price — price seems to be trending downward regardless. 💦 3. Soft Water Quantity increases from Mar (2051.88) to Jul (2122.84). Prices remain very low and relatively flat: ~$49–63 range. The price drop in Mar ($52.44) and May ($49.11) appears even when quantity is low, suggesting price is not tightly correlated with quantity for soft water. 🔍 Key Observations: | D25: 🧩 1. Hard + Soft Water Combined Higher quantity months (e.g., Jan: 4596.38) tend to have higher prices (Jan: $172.78). As quantity decreases (Mar: 4255.63), prices also drop (Mar: $163.00). Suggests a positive relationship: when demand is high, price is high. 💧 2. Hard Water Quantity remains relatively stable (range: ~2200–2500), but price decreases steadily: Jan: $110.48 → Jul: $92.81 Even when quantity slightly increases (e.g., Jul), price does not increase. Implies a weak or no clear link between hard water quantity and price — price seems to be trending downward regardless. 💦 3. Soft Water Quantity increases from Mar (2051.88) to Jul (2122.84). Prices remain very low and relatively flat: ~$49–63 range. The price drop in Mar ($52.44) and May ($49.11) appears even when quantity is low, suggesting price is not tightly correlated with quantity for soft water. 🔍 Key Observations: | E25: 🧩 1. Hard + Soft Water Combined Higher quantity months (e.g., Jan: 4596.38) tend to have higher prices (Jan: $172.78). As quantity decreases (Mar: 4255.63), prices also drop (Mar: $163.00). Suggests a positive relationship: when demand is high, price is high. 💧 2. Hard Water Quantity remains relatively stable (range: ~2200–2500), but price decreases steadily: Jan: $110.48 → Jul: $92.81 Even when quantity slightly increases (e.g., Jul), price does not increase. Implies a weak or no clear link between hard water quantity and price — price seems to be trending downward regardless. 💦 3. Soft Water Quantity increases from Mar (2051.88) to Jul (2122.84). Prices remain very low and relatively flat: ~$49–63 range. The price drop in Mar ($52.44) and May ($49.11) appears even when quantity is low, suggesting price is not tightly correlated with quantity for soft water. 🔍 Key Observations: | F25: 🧩 1. Hard + Soft Water Combined Higher quantity months (e.g., Jan: 4596.38) tend to have higher prices (Jan: $172.78). As quantity decreases (Mar: 4255.63), prices also drop (Mar: $163.00). Suggests a positive relationship: when demand is high, price is high. 💧 2. Hard Water Quantity remains relatively stable (range: ~2200–2500), but price decreases steadily: Jan: $110.48 → Jul: $92.81 Even when quantity slightly increases (e.g., Jul), price does not increase. Implies a weak or no clear link between hard water quantity and price — price seems to be trending downward regardless. 💦 3. Soft Water Quantity increases from Mar (2051.88) to Jul (2122.84). Prices remain very low and relatively flat: ~$49–63 range. The price drop in Mar ($52.44) and May ($49.11) appears even when quantity is low, suggesting price is not tightly correlated with quantity for soft water. 🔍 Key Observations:
A26: Previously we covered how we could make use of scatter plots to help us visually compare the changes between price and quantity to determine whether a relationship is elastic or inelastic.
A27: Let's create a scatter plot to compare the price / quantity columns for the 3 different permutations of: 1) Hard + Soft Water, 2) Hard Water and 3) Soft Water.
A28: Q2. Using the data you've calculated above in Q1, with the Y-axis set to Avg. WMBP and X-axis set to Avg. Qty of Water Demanded, create three (3) separate charts showing the Overall (Hard Water + Soft Water) Scatter Plot, Hard Water Scatter Plot and Soft Water Scatter Plot.
A39: However, simply eyeing the data isn't sufficient. It's important we also take into account a quantitative lens. Whenever we see a visual trend, we can try and ascertain this by asking ourselves; what theorems would help disprove this?
A40: In this case, we're aware of a particular economic construct known as the Elasticity of Demand Coefficient (EoD).
A41: Now the EoD enables us to calculate elasticity and determine that if it is greater than 1, it is elastic, and if it is, less than 1, it is inelastic. This is much more absolute than simply eyeballing the data.
A42: Let's close out our Economic Market Analysis by calculating the EoD coefficient for each water product and determining the overall elasticity for each month, before averaging for the year.
G44: Let's review the example we've demonstrated on the left.
G45: We'll demonstrate with an example here.
G46: We have two months worth of pricing and quantity data we need to analyze to determine February's Elasticity Of Demand Coefficient.
H47: January | I47: February
G48: Price | H48: 74 | I48: 86
G49: Quantity | H49: 80 | I49: 100
G50: Let's now calculate the respective changes.
G51: Price % Change | H51: (86 - 74) / 74 | I51: =(I48-H48)/H48 -> 0.16216216
G52: Quantity % Change | H52: (100 - 80 ) / 80 | I52: =(I49-H49)/H49 -> 0.25
...

Sheet What-If Analysis
A1: What IF Analysis - Part III.
A2: In the previous sections, we've examined the Elasticies and Inelasticies of Products. We've also gone ahead with calculating our first economic metric, Cost to Produce per Desalination Unit.
A3: We're now at the final stage of this economic case study!
A4: Economic Data Analysis, as you know by now, is focused on understanding the drivers which impact supply and demand and translating these into actionable business insights. It is also used for better understanding when certain decisions should be made (e.g. Should we look at selling this product now or in a few months time for improved earnings?)
A5: Now we're aware that Southern Water Corp. has been considering to perform a major maintenance activity for one of its major desalination plants, Surjek. The business hypothesis is that it is best for us to perform the maintenance for Surjek in the first quarter of the year going forward (January-15 to March-15).
A6: However, we don't have data going all the way to January-15 to March-15. What we do have however, is data from July 2013 - June 2014. We also have pricing data from January 2014 - December 2014.
A7: We can't use what we don't have - so let's use what we do have. In other words, we'll be making use of the data in the Water Trading Repository Tables to forecast what the demand profile may look like for the future.
A8: This means when we reference Jan-15, we'll instead use Jan-14's data as a placeholder. For Feb-15, we do the same and use Feb-14 etc.
A9: Let's get started!
A11: Q8. Complete the table below with the Average Monthly Water Balancing Market Price (WBMP) and Average Market Water Demand using data from the Water Trading Repository Table. Create one LINE chart trending the Average Water Balancing Price from Jul-14 to Jun-15. Create one COLUMN chart showing the Average Water Market Demand from Jul-14 to Jun-15. Compare these side-by-side. What do you observe? Note: Consider using the AVERAGEIFS function to help you address this question if you're stuck! https://support.microsoft.com/en-us/office/averageifs-function-48910c45-1fc0-4389-a028-f7c5c3001690
A12: Hint: Use the Water Trading Repository Table Data as your data source. Even though the date/time doesn't align, we can use the information as a proxy for the 2014/2015 data. It may also help to graph out the data and see if any trends become particularly obvious...!
A13: Source | E13: 41821 | F13: 41852 | G13: 41883 | H13: 41913 | I13: 41944 | J13: 41974 | K13: 42005 | L13: 42036 | M13: 42064 | N13: 42095 | O13: 42125 | P13: 42156 | Q13: Total
E14: =MONTH(E13) -> 7 | F14: =MONTH(F13) -> 8 | G14: =MONTH(G13) -> 9 | H14: =MONTH(H13) -> 10 | I14: =MONTH(I13) -> 11 | J14: =MONTH(J13) -> 12 | K14: =MONTH(K13) -> 1 | L14: =MONTH(L13) -> 2 | ... P14: =MONTH(P13) -> 6
A15: Water Trading Repository Table | B15: Average Water Balancing Market Price | E15: =AVERAGEIFS('Water Trading Repository Table'!$C:$C, 'Water Trading Repository Table'!$A:$A, ">=" & E$13, 'Water Trading Repository Table'!$A:$A, "<" & EDATE(E$13, 1)) -> 76.60272 | F15: =AVERAGEIFS('Water Trading Repository Table'!$C:$C, 'Water Trading Repository Table'!$A:$A, ">=" & F$13, 'Water Trading Repository Table'!$A:$A, "<" & EDATE(F$13, 1)) -> 74.93254 | G15: =AVERAGEIFS('Water Trading Repository Table'!$C:$C, 'Water Trading Repository Table'!$A:$A, ">=" & G$13, 'Water Trading Repository Table'!$A:$A, "<" & EDATE(G$13, 1)) -> 74.06632 | H15: =AVERAGEIFS('Water Trading Repository Table'!$C:$C, 'Water Trading Repository Table'!$A:$A, ">=" & H$13, 'Water Trading Repository Table'!$A:$A, "<" & EDATE(H$13, 1)) -> 75.093149 | I15: =AVERAGEIFS('Water Trading Repository Table'!$C:$C, 'Water Trading Repository Table'!$A:$A, ">=" & I$13, 'Water Trading Repository Table'!$A:$A, "<" & EDATE(I$13, 1)) -> 73.700956 | J15: =AVERAGEIFS('Water Trading Repository Table'!$C:$C, 'Water Trading Repository Table'!$A:$A, ">=" & J$13, 'Water Trading Repository Table'!$A:$A, "<" & EDATE(J$13, 1)) -> 74.376657 | K15: =AVERAGEIFS('Water Trading Repository Table'!$C:$C, 'Water Trading Repository Table'!$A:$A, ">=1/1/2014", 'Water Trading Repository Table'!$A:$A, "<2/1/2014") -> 86.391757 | L15: =AVERAGEIFS('Water Trading Repository Table'!$C:$C, 'Water Trading Repository Table'!$A:$A, ">=2/1/2014", 'Water Trading Repository Table'!$A:$A, "<3/1/2014") -> 86.82949 | M15: =AVERAGEIFS('Water Trading Repository Table'!$C:$C, 'Water Trading Repository Table'!$A:$A, ">=3/1/2014", 'Water Trading Repository Table'!$A:$A, "<4/1/2014") -> 81.499891 | N15: =AVERAGEIFS('Water Trading Repository Table'!$C:$C, 'Water Trading Repository Table'!$A:$A, ">=4/1/2014", 'Water Trading Repository Table'!$A:$A, "<5/1/2014") -> 72.569232 | O15: =AVERAGEIFS('Water Trading Repository Table'!$C:$C, 'Water Trading Repository Table'!$A:$A, ">=5/1/2014", 'Water Trading Repository Table'!$A:$A, "<6/1/2014") -> 71.259354 | P15: =AVERAGEIFS('Water Trading Repository Table'!$C:$C, 'Water Trading Repository Table'!$A:$A, ">=6/1/2014", 'Water Trading Repository Table'!$A:$A, "<7/1/2014") -> 72.156511 | Q15: =SUM(E15:P15) -> 919.47858
A16: Water Trading Repository Table | B16: Market Water Demand (Mega-Litres) | E16: =AVERAGEIFS('Water Trading Repository Table'!$B:$B, 'Water Trading Repository Table'!$A:$A, ">=" & E$13, 'Water Trading Repository Table'!$A:$A, "<" & EDATE(E$13, 1)) -> 2283.0502 | F16: =AVERAGEIFS('Water Trading Repository Table'!$B:$B, 'Water Trading Repository Table'!$A:$A, ">=" & F$13, 'Water Trading Repository Table'!$A:$A, "<" & EDATE(F$13, 1)) -> 2201.0592 | G16: =AVERAGEIFS('Water Trading Repository Table'!$B:$B, 'Water Trading Repository Table'!$A:$A, ">=" & G$13, 'Water Trading Repository Table'!$A:$A, "<" & EDATE(G$13, 1)) -> 2153.3432 | H16: =AVERAGEIFS('Water Trading Repository Table'!$B:$B, 'Water Trading Repository Table'!$A:$A, ">=" & H$13, 'Water Trading Repository Table'!$A:$A, "<" & EDATE(H$13, 1)) -> 2098.9914 | I16: =AVERAGEIFS('Water Trading Repository Table'!$B:$B, 'Water Trading Repository Table'!$A:$A, ">=" & I$13, 'Water Trading Repository Table'!$A:$A, "<" & EDATE(I$13, 1)) -> 2200.9293 | J16: =AVERAGEIFS('Water Trading Repository Table'!$B:$B, 'Water Trading Repository Table'!$A:$A, ">=" & J$13, 'Water Trading Repository Table'!$A:$A, "<" & EDATE(J$13, 1)) -> 2312.1995 | K16: =AVERAGEIFS('Water Trading Repository Table'!$B:$B, 'Water Trading Repository Table'!$A:$A, ">=1/1/2014", 'Water Trading Repository Table'!$A:$A, "<2/1/2014") -> 2298.1902 | L16: =AVERAGEIFS('Water Trading Repository Table'!$B:$B, 'Water Trading Repository Table'!$A:$A, ">=2/1/2014", 'Water Trading Repository Table'!$A:$A, "<3/1/2014") -> 2406.0919 | M16: =AVERAGEIFS('Water Trading Repository Table'!$B:$B, 'Water Trading Repository Table'!$A:$A, ">=3/1/2014", 'Water Trading Repository Table'!$A:$A, "<4/1/2014") -> 2127.8145 | N16: =AVERAGEIFS('Water Trading Repository Table'!$B:$B, 'Water Trading Repository Table'!$A:$A, ">=4/1/2014", 'Water Trading Repository Table'!$A:$A, "<5/1/2014") -> 2185.7998 | O16: =AVERAGEIFS('Water Trading Repository Table'!$C:$C, 'Water Trading Repository Table'!$A:$A, ">=5/1/2014", 'Water Trading Repository Table'!$A:$A, "<6/1/2014") -> 71.259354 | P16: =AVERAGEIFS('Water Trading Repository Table'!$C:$C, 'Water Trading Repository Table'!$A:$A, ">=6/1/2014", 'Water Trading Repository Table'!$A:$A, "<7/1/2014") -> 72.156511 | Q16: =SUM(E16:P16) -> 22410.885
A36: Place your answer here | B36: This image contains two related charts that give insights into water market pricing and demand trends from July 2014 to June 2015: Left Chart: Average Water Balancing Price Trend: The line chart shows the monthly average price of water balancing. Key Observations: Prices hovered around $75-$80 from July 2014 to December 2014. There was a sharp increase in January and February 2015, peaking close to $88. Prices dropped significantly after February, reaching the lowest point in May 2015 (around $70), before a slight uptick in June. Right Chart: Average Water Market Demand Trend: The bar chart displays monthly average water demand in Megaliters (MegaL). Key Observations: Demand fluctuated around 2,100–2,300 MegaL in most months. The highest spike in demand occurred in February 2015, reaching about 2,430 MegaL. Demand dropped sharply in March, followed by relatively lower and stable levels until June 2015. Interpretation / Insights: February 2015 stands out: It shows the highest price and highest demand. This suggests a positive relationship between market demand and pricing—when demand surged, so did the price. After February, both demand and price declined, possibly indicating seasonal effects or policy changes. This could reflect a strain on water supply in early 2015, leading to a market spike.
A40: We've identified a particular trend in our earlier analysis; It seems that one of the quarters tends to have the highest prices. As we perform our what-if analysis it's important we can clearly identify the quarter we should recommend to perform our major maintenance. Let's calculate this below and land on a quarter we can propose to focus our analysis on. Q9. Complete the table below identifying which quarter has the highest/lowest prices with the respective Average Quarterly Water Volumes. What do you notice? Note: Reference the Water Trading Repository Table for your calculations.
A41: As you'll be calculating the Quarterly Averages, this will require you to use an AVERAGEIFS statement combined with logical and numerical operators.
A42: For example = AVERAGEIFS(Monthly_Price, Month_Range, ">="&1, Month_Range, "<="&3). This says, give me the Average Price for the periods between January (1) and March (3).
A43: Quarter | C43: Average Quarterly Price Per Trading Period | D43: Average Quarterly Water Demand Per Trading Period
A44: Quarter 1 (January - March) | C44: =AVERAGEIFS('Water Trading Repository Table'!$C:$C, 'Water Trading Repository Table'!$D:$D, ">=1", 'Water Trading Repository Table'!$D:$D, "<=3") -> 84.842965 | D44: =AVERAGEIFS('Water Trading Repository Table'!$B:$B, 'Water Trading Repository Table'!$D:$D, ">=1", 'Water Trading Repository Table'!$D:$D, "<=3") -> 2273.0747
A45: Quarter 2 (April to June) | C45: =AVERAGEIFS('Water Trading Repository Table'!$C:$C, 'Water Trading Repository Table'!$D:$D, ">=4", 'Water Trading Repository Table'!$D:$D, "<=6") -> 71.986948 | D45: =AVERAGEIFS('Water Trading Repository Table'!$B:$B, 'Water Trading Repository Table'!$D:$D, ">=4", 'Water Trading Repository Table'!$D:$D, "<=6") -> 2186.6569
A46: Quarter 3 (July to September) | C46: =AVERAGEIFS('Water Trading Repository Table'!$C:$C, 'Water Trading Repository Table'!$D:$D, ">=7", 'Water Trading Repository Table'!$D:$D, "<=9") -> 75.212855 | D46: =AVERAGEIFS('Water Trading Repository Table'!$B:$B, 'Water Trading Repository Table'!$D:$D, ">=7", 'Water Trading Repository Table'!$D:$D, "<=9") -> 2213.1271
A47: Quarter 4 (October to December) | C47: =AVERAGEIFS('Water Trading Repository Table'!$C:$C, 'Water Trading Repository Table'!$D:$D, ">=10", 'Water Trading Repository Table'!$D:$D, "<=12") -> 74.397746 | D47: =AVERAGEIFS('Water Trading Repository Table'!$B:$B, 'Water Trading Repository Table'!$D:$D, ">=10", 'Water Trading Repository Table'!$D:$D, "<=12") -> 2204.0739
A49: Place your answer here | B49: Q1 (Jan–Mar) is the strongest quarter, showing both the highest prices and demand — likely due to high consumption or limited supply in that period. Q2 (Apr–Jun) is the weakest quarter, with the lowest price and demand, suggesting it may be an ideal time for a maintenance outage since it would have the least market impact. Q3 and Q4 show stable, mid-range performance.
A51: We've now completed the first part of our What-If Analysis. We've identified that the best period for us to perform a maintenance event is during a specific quarter. We now need to finalize our recommendation by showing the What-If Impact of our analysis. In Other words, if we were to perform this Maintenance Outage for Quarter 1, Quarter 2, Quarter Three and Quarter Four - what impact would this have on our revenues?
A53: Q10. Fill out the table(s) below explaining why the Quarter you are proposing is the best option for Southern Water Corp. when considering the impact on Revenues. We recommend accompanying the table with an appropriate visual to help highlight the point you are trying to make. Note: Recall that for the Quarter you are recommending for a maintenance outage, the revenues for that entire quarter for Surjek will be 0. Remember, if we are producing no water - we can't earn revenues.
E54: Q3 | F54: Q3 | G54: Q3 | H54: Q4 | I54: Q4 | J54: Q4 | K54: Q1 | L54: Q1 | M54: Q1 | N54: Q2 | O54: Q2 | P54: Q2
A55: Account Type | B55: Unit | C55: Value Driver | E55: 41456 | F55: 41487 | G55: 41518 | H55: 41548 | I55: 41579 | J55: 41609 | K55: 41640 | L55: 41671 | M55: 41699 | N55: 41730 | O55: 41760 | P55: 41791 | Q55: Total
A56: Financial Actual | B56: Kootha | C56: Revenues | E56: =SUMIFS('Data Repository Table'!$J:$J, 'Data Repository Table'!$A:$A, "Financial Actual", 'Data Repository Table'!$C:$C, "Kootha", 'Data Repository Table'!$B:$B, "Revenues", 'Data Repository Table'!$D:$D, ">=" & E$55, 'Data Repository Table'!$D:$D, "<" & EDATE(E$55, 1)) -> 5914581.2 | F56: =SUMIFS('Data Repository Table'!$J:$J, 'Data Repository Table'!$A:$A, "Financial Actual", 'Data Repository Table'!$C:$C, "Kootha", 'Data Repository Table'!$B:$B, "Revenues", 'Data Repository Table'!$D:$D, ">=" & F$55, 'Data Repository Table'!$D:$D, "<" & EDATE(F$55, 1)) -> 5696664.2 | G56: =SUMIFS('Data Repository Table'!$J:$J, 'Data Repository Table'!$A:$A, "Financial Actual", 'Data Repository Table'!$C:$C, "Kootha", 'Data Repository Table'!$B:$B, "Revenues", 'Data Repository Table'!$D:$D, ">=" & G$55, 'Data Repository Table'!$D:$D, "<" & EDATE(G$55, 1)) -> 5260681.8 | H56: =SUMIFS('Data Repository Table'!$J:$J, 'Data Repository Table'!$A:$A, "Financial Actual", 'Data Repository Table'!$C:$C, "Kootha", 'Data Repository Table'!$B:$B, "Revenues", 'Data Repository Table'!$D:$D, ">=" & H$55, 'Data Repository Table'!$D:$D, "<" & EDATE(H$55, 1)) -> 5221955.5 | I56: =SUMIFS('Data Repository Table'!$J:$J, 'Data Repository Table'!$A:$A, "Financial Actual", 'Data Repository Table'!$C:$C, "Kootha", 'Data Repository Table'!$B:$B, "Revenues", 'Data Repository Table'!$D:$D, ">=" & I$55, 'Data Repository Table'!$D:$D, "<" & EDATE(I$55, 1)) -> 5514147.2 | J56: =SUMIFS('Data Repository Table'!$J:$J, 'Data Repository Table'!$A:$A, "Financial Actual", 'Data Repository Table'!$C:$C, "Kootha", 'Data Repository Table'!$B:$B, "Revenues", 'Data Repository Table'!$D:$D, ">=" & J$55, 'Data Repository Table'!$D:$D, "<" & EDATE(J$55, 1)) -> 5380892.2 | K56: =SUMIFS('Data Repository Table'!$J:$J, 'Data Repository Table'!$A:$A, "Financial Actual", 'Data Repository Table'!$C:$C, "Kootha", 'Data Repository Table'!$B:$B, "Revenues", 'Data Repository Table'!$D:$D, ">=" & K$55, 'Data Repository Table'!$D:$D, "<" & EDATE(K$55, 1)) -> 7822599.7 | L56: =SUMIFS('Data Repository Table'!$J:$J, 'Data Repository Table'!$A:$A, "Financial Actual", 'Data Repository Table'!$C:$C, "Kootha", 'Data Repository Table'!$B:$B, "Revenues", 'Data Repository Table'!$D:$D, ">=" & L$55, 'Data Repository Table'!$D:$D, "<" & EDATE(L$55, 1)) -> 6924324.6 | ... P56: =SUMIFS('Data Repository Table'!$J:$J, 'Data Repository Table'!$A:$A, "Financial Actual", 'Data Repository Table'!$C:$C, "Kootha", 'Data Repository Table'!$B:$B, "Revenues", 'Data Repository Table'!$D:$D, ">=" & P$55, 'Data Repository Table'!$D:$D, "<" & EDATE(P$55, 1)) -> 5184163.9 | Q56: =SUM(E56:P56) -> 70944957
A57: Financial Actual | B57: Surjek | C57: Revenues | E57: =SUMIFS('Data Repository Table'!$J:$J, 'Data Repository Table'!$A:$A, "Financial Actual", 'Data Repository Table'!$C:$C, "Surjek", 'Data Repository Table'!$B:$B, "Revenues", 'Data Repository Table'!$D:$D, ">=" & E$55, 'Data Repository Table'!$D:$D, "<" & EDATE(E$55, 1)) -> 17328051 | F57: =SUMIFS('Data Repository Table'!$J:$J, 'Data Repository Table'!$A:$A, "Financial Actual", 'Data Repository Table'!$C:$C, "Surjek", 'Data Repository Table'!$B:$B, "Revenues", 'Data Repository Table'!$D:$D, ">=" & F$55, 'Data Repository Table'!$D:$D, "<" & EDATE(F$55, 1)) -> 14604314 | G57: =SUMIFS('Data Repository Table'!$J:$J, 'Data Repository Table'!$A:$A, "Financial Actual", 'Data Repository Table'!$C:$C, "Surjek", 'Data Repository Table'!$B:$B, "Revenues", 'Data Repository Table'!$D:$D, ">=" & G$55, 'Data Repository Table'!$D:$D, "<" & EDATE(G$55, 1)) -> 16135900 | H57: =SUMIFS('Data Repository Table'!$J:$J, 'Data Repository Table'!$A:$A, "Financial Actual", 'Data Repository Table'!$C:$C, "Surjek", 'Data Repository Table'!$B:$B, "Revenues", 'Data Repository Table'!$D:$D, ">=" & H$55, 'Data Repository Table'!$D:$D, "<" & EDATE(H$55, 1)) -> 15151633 | I57: =SUMIFS('Data Repository Table'!$J:$J, 'Data Repository Table'!$A:$A, "Financial Actual", 'Data Repository Table'!$C:$C, "Surjek", 'Data Repository Table'!$B:$B, "Revenues", 'Data Repository Table'!$D:$D, ">=" & I$55, 'Data Repository Table'!$D:$D, "<" & EDATE(I$55, 1)) -> 13832901 | J57: =SUMIFS('Data Repository Table'!$J:$J, 'Data Repository Table'!$A:$A, "Financial Actual", 'Data Repository Table'!$C:$C, "Surjek", 'Data Repository Table'!$B:$B, "Revenues", 'Data Repository Table'!$D:$D, ">=" & J$55, 'Data Repository Table'!$D:$D, "<" & EDATE(J$55, 1)) -> 15562960 | K57: 0 | L57: 0 | M57: 0 | N57: =SUMIFS('Data Repository Table'!$J:$J, 'Data Repository Table'!$A:$A, "Financial Actual", 'Data Repository Table'!$C:$C, "Surjek", 'Data Repository Table'!$B:$B, "Revenues", 'Data Repository Table'!$D:$D, ">=" & N$55, 'Data Repository Table'!$D:$D, "<" & EDATE(N$55, 1)) -> 18268435 | O57: =SUMIFS('Data Repository Table'!$J:$J, 'Data Repository Table'!$A:$A, "Financial Actual", 'Data Repository Table'!$C:$C, "Surjek", 'Data Repository Table'!$B:$B, "Revenues", 'Data Repository Table'!$D:$D, ">=" & O$55, 'Data Repository Table'!$D:$D, "<" & EDATE(O$55, 1)) -> 14627298 | P57: =SUMIFS('Data Repository Table'!$J:$J, 'Data Repository Table'!$A:$A, "Financial Actual", 'Data Repository Table'!$C:$C, "Surjek", 'Data Repository Table'!$B:$B, "Revenues", 'Data Repository Table'!$D:$D, ">=" & P$55, 'Data Repository Table'!$D:$D, "<" & EDATE(P$55, 1)) -> 16164167 | Q57: =SUM(E57:P57) -> 1.4167566e+08
A58: Financial Actual | B58: Jutik | C58: Revenues | E58: =SUMIFS('Data Repository Table'!$J:$J, 'Data Repository Table'!$A:$A, "Financial Actual", 'Data Repository Table'!$C:$C, "Jutik", 'Data Repository Table'!$B:$B, "Revenues", 'Data Repository Table'!$D:$D, ">=" & E$55, 'Data Repository Table'!$D:$D, "<" & EDATE(E$55, 1)) -> 12716847 | F58: =SUMIFS('Data Repository Table'!$J:$J, 'Data Repository Table'!$A:$A, "Financial Actual", 'Data Repository Table'!$C:$C, "Jutik", 'Data Repository Table'!$B:$B, "Revenues", 'Data Repository Table'!$D:$D, ">=" & F$55, 'Data Repository Table'!$D:$D, "<" & EDATE(F$55, 1)) -> 13050244 | G58: =SUMIFS('Data Repository Table'!$J:$J, 'Data Repository Table'!$A:$A, "Financial Actual", 'Data Repository Table'!$C:$C, "Jutik", 'Data Repository Table'!$B:$B, "Revenues", 'Data Repository Table'!$D:$D, ">=" & G$55, 'Data Repository Table'!$D:$D, "<" & EDATE(G$55, 1)) -> 13235473 | H58: =SUMIFS('Data Repository Table'!$J:$J, 'Data Repository Table'!$A:$A, "Financial Actual", 'Data Repository Table'!$C:$C, "Jutik", 'Data Repository Table'!$B:$B, "Revenues", 'Data Repository Table'!$D:$D, ">=" & H$55, 'Data Repository Table'!$D:$D, "<" & EDATE(H$55, 1)) -> 11815762 | I58: =SUMIFS('Data Repository Table'!$J:$J, 'Data Repository Table'!$A:$A, "Financial Actual", 'Data Repository Table'!$C:$C, "Jutik", 'Data Repository Table'!$B:$B, "Revenues", 'Data Repository Table'!$D:$D, ">=" & I$55, 'Data Repository Table'!$D:$D, "<" & EDATE(I$55, 1)) -> 11881724 | J58: =SUMIFS('Data Repository Table'!$J:$J, 'Data Repository Table'!$A:$A, "Financial Actual", 'Data Repository Table'!$C:$C, "Jutik", 'Data Repository Table'!$B:$B, "Revenues", 'Data Repository Table'!$D:$D, ">=" & J$55, 'Data Repository Table'!$D:$D, "<" & EDATE(J$55, 1)) -> 11127132 | K58: =SUMIFS('Data Repository Table'!$J:$J, 'Data Repository Table'!$A:$A, "Financial Actual", 'Data Repository Table'!$C:$C, "Jutik", 'Data Repository Table'!$B:$B, "Revenues", 'Data Repository Table'!$D:$D, ">=" & K$55, 'Data Repository Table'!$D:$D, "<" & EDATE(K$55, 1)) -> 15491089 | L58: =SUMIFS('Data Repository Table'!$J:$J, 'Data Repository Table'!$A:$A, "Financial Actual", 'Data Repository Table'!$C:$C, "Jutik", 'Data Repository Table'!$B:$B, "Revenues", 'Data Repository Table'!$D:$D, ">=" & L$55, 'Data Repository Table'!$D:$D, "<" & EDATE(L$55, 1)) -> 15776843 | ... P58: =SUMIFS('Data Repository Table'!$J:$J, 'Data Repository Table'!$A:$A, "Financial Actual", 'Data Repository Table'!$C:$C, "Jutik", 'Data Repository Table'!$B:$B, "Revenues", 'Data Repository Table'!$D:$D, ">=" & P$55, 'Data Repository Table'!$D:$D, "<" & EDATE(P$55, 1)) -> 15120322 | Q58: =SUM(E58:P58) -> 1.6366523e+08
A62: Fill this table out with Surjek's Sales Revenue from Jul-13 to Jun-14. However, when evaluating Q1, Q2, Q3 or Q4 is best, note that if you choose Q1, you'll need to put down a 0 in the values from January to March. This is because we're saying the unit will be offline then and not producing any water. This means at any point in our simulation for Q1 to Q4, we will only have 9 Month's worth of revenue-producing months, as the other 3 are offline due to outages. Please repeat this from Q2 to Q4.
A63: Now If we perform the Maintenance Outage for Surjek in Q1, Q2, Q3 or Q4 our Revenues will be…
A64: Account Type | B64: Unit | C64: Value Driver | D64: Quarter | E64: 41456 | F64: 41487 | G64: 41518 | H64: 41548 | I64: 41579 | J64: 41609 | K64: 41640 | L64: 41671 | M64: 41699 | N64: 41730 | O64: 41760 | P64: 41791 | Q64: Total | R64: % Revenue Reduction
